function catchAsyncException(func) {
  return (...args) => {
    func.apply(null, args).catch((err) => {
      alert('Something went wrong! ðŸ˜¢');
      console.error(err);
      return;
    });
  };
}
